Workbook

Sheet 00 Guia
A1: Mentor Comercial — Motor de Follow-up v1.0
A2: Dicionário de regras, cadências, scripts, score e simulador para validação.
A3: Seção | B3: Conteúdo
A4: Objetivo | B4: Planilha para testar a lógica do Motor de Follow-up do Mentor Comercial antes de implementar no sistema. | D4: Indicador | E4: Quantidade
A5: Conceito | B5: O vendedor informa a situação atual. O Mentor calcula objetivo, próximo passo, cadência, script, score, prioridade e integração com Central de Execução. | D5: Status mapeados | E5: 86
A6: Canais oficiais | B6: Porta, Internet e Carteira. Origens como indicação, marketplace, feirão, pós-venda e lead antigo entram como origem detalhada dentro de Carteira. | D6: Scripts cadastrados | E6: 77
A7: Como testar | B7: Use a aba '08 Teste_Clientes'. Escolha um Status ID e ajuste os campos de score/urgência para ver recomendação, prioridade e central. | D7: Cadências | E7: 13
A8: Fonte interna | B8: Regras definidas na conversa do projeto MX Performance + referência do arquivo FLUXO DE ACOMPANHAMENTO DE CLIENTES.pdf. | D8: Regras de transição | E8: 52
A9: Observação | B9: Esta é uma matriz operacional v1.0. Não é prompt final de sistema; serve para validação da lógica. | D9: Cenários de teste | E9: 15
D12: Família | E12: Qtd
D13: Contato | E13: 11
D14: Financiamento | E14: 9
D15: Negociação | E15: 14
D16: Perda e Futuro | E16: 6
D17: Qualificação | E17: 9
D18: Relacionamento | E18: 11
D19: Troca | E19: 9
D20: Venda e Entrega | E20: 7
D21: Visita | E21: 10

Sheet 01 Canais
A1: Canais Comerciais Oficiais
A2: Canal Comercial ≠ origem detalhada. Preservar canal de entrada e canal de venda.
A3: Canal Comercial | B3: Conceito oficial | C3: O que mede | D3: Entram como origem detalhada | E3: Regras importantes | F3: Exemplos
A4: Porta | B4: Cliente que entra espontaneamente na loja, sem agendamento produzido pela equipe. | C4: Força de atração da loja e capacidade de conversão no atendimento presencial. | D4: Entrada espontânea, passagem em frente, viu anúncio/site/rede social mas foi direto à loja. | E4: Se não houve ação direta de agendamento do vendedor, a venda é Porta. Se não comprou na hora e depois fechou por follow-up do vendedor, o canal de venda pode ser Carteira. | F4: Cliente viu anúncio, não chamou no WhatsApp, foi direto à loja e comprou.
A5: Internet | B5: Lead produzido pela empresa em que o vendedor atuou para transformar contato em agendamento e visita. | C5: Geração de leads da empresa + capacidade do vendedor de transformar lead em visita. | D5: Lead do Instagram da loja, Google Ads da loja, site, portal/campanha da empresa. | E5: A venda é Internet quando existe lead da empresa + ação do vendedor que precede agendamento e visita. | F5: Lead do site recebe contato do vendedor, agenda visita e compra.
A6: Carteira | B6: Venda ou oportunidade gerada por ação direta do vendedor. | C6: Capacidade do vendedor de gerar negócios por relacionamento, prospecção e iniciativa própria. | D6: Indicação, prospecção, cliente antigo, pós-venda, garantia, lead com mais de 90 dias, anúncio próprio, marketplace próprio, OLX própria, tráfego próprio, feirão trabalhado pelo vendedor. | E6: Origens diversas entram como Carteira. Preservar canal de entrada e canal de venda separados. | F6: Lead antigo de Internet é reativado após 90 dias e compra: canalEntrada=Internet, canalVenda=Carteira.

Sheet 02 Status
A1: Dicionário de Status e Decisão do Mentor
A2: Cada status gera objetivo, próximo passo, cadência, script e regra de Central.
A3: Status ID | B3: Canal | C3: Família | D3: Status atual | E3: Definição / quando usar | F3: Origem | G3: Responsável atual | H3: Temperatura | I3: Objetivo atual | J3: Próximo passo | K3: Cadência | L3: Script base | M3: Potencial | N3: Entra na Central quando | O3: Ativo na Carteira | P3: Orientação do Mentor | Q3: Resultados principais | R3: Observações / regras
A4: INT-C01 | B4: Internet | C4: Contato | D4: Primeiro contato pendente | E4: Lead cadastrado e nenhuma tentativa efetiva realizada | F4: Automático | G4: Vendedor | H4: Morno | I4: Iniciar conversa | J4: Enviar primeira abordagem | K4: CAD-01 | L4: SCR-INT-CAD01-T1 | M4: Baixo | N4: Próxima ação hoje | O4: Sim | P4: O objetivo é iniciar conversa sem parecer cobrança. | Q4: Mensagem enviada; Cliente respondeu; Número inválido; Não deseja contato
A5: INT-C02 | B5: Internet | C5: Contato | D5: Sem resposta — cadência ativa | E5: Vendedor enviou mensagem e cliente ainda não respondeu | F5: Derivado/Informado | G5: Cliente | H5: Morno/Frio | I5: Iniciar conversa | J5: Executar tentativa atual | K5: CAD-01 | L5: SCR-INT-CAD01-T{n} | M5: Baixo | N5: Tentativa da cadência vence hoje | O5: Sim | P5: Execute a próxima tentativa sem mudar o status se o cliente não respondeu. | Q5: Cliente respondeu; Sem resposta; Cadência concluída | R5: Não penalizar score se a tentativa foi executada no prazo.
A6: INT-C03 | B6: Internet | C6: Contato | D6: Resposta recebida — atendimento pendente | E6: Cliente respondeu e precisa ser tratado pelo vendedor | F6: Automático/Informado | G6: Vendedor | H6: Morno | I6: Entender a situação | J6: Responder e atualizar status | K6: Ação imediata | L6: SCR-QUAL-01 | M6: Médio | N6: Imediatamente/Hoje | O6: Sim | P6: Cliente respondeu: a bola está com o vendedor. | Q6: Qualificação; Visita; Proposta; Outra situação | R6: Prioridade sobe e score cai se o vendedor não tratar dentro do SLA.
A7: INT-C04 | B7: Internet | C7: Contato | D7: Contato inválido | E7: Telefone ou WhatsApp não permite contato | F7: Informado | G7: Vendedor | H7: - | I7: Validar contato | J7: Corrigir telefone ou confirmar impossibilidade | K7: Verificação única | L7: SCR-INTERNO | M7: Baixo | N7: Quando informado | O7: Sim | P7: Confirme se existe outro número antes de encerrar. | Q7: Corrigiu contato; Encerrar
A8: INT-C05 | B8: Internet | C8: Contato | D8: Cliente não deseja contato | E8: Cliente solicitou interrupção das mensagens | F8: Informado | G8: Encerrado | H8: - | I8: Respeitar solicitação | J8: Encerrar contato | K8: Sem cadência | L8: SCR-INTERNO | M8: Baixo | N8: Não entra | O8: Não | P8: Não insistir. Preservar histórico. | Q8: Encerrar
A9: INT-C06 | B9: Internet | C9: Contato | D9: Cadência concluída sem resposta | E9: Todas as tentativas foram executadas sem retorno | F9: Automático | G9: Encerrado | H9: Frio | I9: Preservar oportunidade | J9: Retirar da Carteira Ativa | K9: Sem ação imediata | L9: SCR-INTERNO | M9: Baixo | N9: Não entra | O9: Não | P9: Cliente sai da rotina diária, mas pode virar missão futura. | Q9: Plano de Ataque futuro | R9: Não transformar automaticamente em perda.
A10: INT-Q01 | B10: Internet | C10: Qualificação | D10: Qualificação inicial pendente | E10: Cliente respondeu, mas ainda não há informações suficientes | F10: Informado | G10: Vendedor | H10: Morno | I10: Entender necessidade | J10: Perguntar uso e prazo | K10: CAD-04 | L10: SCR-QUAL-01 | M10: Médio | N10: Próxima ação hoje | O10: Sim | P10: Antes de falar de preço, entenda uso, prazo e necessidade. | Q10: Veículo não definido; Veículo definido; Compra futura
A11: INT-Q02 | B11: Internet | C11: Qualificação | D11: Veículo ainda não definido | E11: Uso e intenção conhecidos, mas modelo/categoria não definidos | F11: Informado | G11: Vendedor | H11: Morno | I11: Definir solução | J11: Identificar modelo, categoria e faixa | K11: CAD-04 | L11: SCR-QUAL-02 | M11: Médio | N11: Tentativa vence hoje | O11: Sim | P11: Ajude o cliente a escolher antes de pressionar por visita. | Q11: Veículo definido; Compra futura; Aguardando veículo compatível
A12: INT-Q03 | B12: Internet | C12: Qualificação | D12: Veículo definido — condição não qualificada | E12: Veículo conhecido, mas faltam prazo, orçamento, troca ou financiamento | F12: Informado | G12: Vendedor | H12: Morno | I12: Entender viabilidade | J12: Perguntar prazo, troca e financiamento | K12: CAD-04 | L12: SCR-QUAL-03 | M12: Médio | N12: Tentativa vence hoje | O12: Sim | P12: Complete a qualificação para saber o melhor próximo passo. | Q12: Cliente qualificado; Troca; Financiamento; Compra futura
A13: INT-Q04 | B13: Internet | C13: Qualificação | D13: Cliente qualificado sem visita | E13: Necessidade, veículo e prazo conhecidos, mas não existe visita | F13: Sugerido | G13: Vendedor | H13: Quente | I13: Gerar visita | J13: Convidar para visita | K13: CAD-02 | L13: SCR-VISITA-CAD02-T1 | M13: Alto | N13: Tentativa vence hoje | O13: Sim | P13: Transforme a qualificação em compromisso presencial. | Q13: Visita em definição; Visita agendada; Não quer visitar
A14: INT-Q05 | B14: Internet | C14: Qualificação | D14: Compra planejada para o futuro | E14: Cliente declarou que não comprará agora | F14: Informado | G14: Data | H14: Frio/Morno | I14: Preservar oportunidade | J14: Programar data de retomada | K14: CAD-12 | L14: SCR-FUTURO-01 | M14: Baixo | N14: Quando a data chegar | O14: Não até ativar | P14: Não force agora. Programe o retorno para o momento certo. | Q14: Contato futuro programado
A15: INT-Q06 | B15: Internet | C15: Qualificação | D15: Aguardando veículo compatível | E15: Cliente qualificado, mas não há veículo adequado disponível | F15: Informado | G15: Loja | H15: Morno | I15: Encontrar produto | J15: Registrar critérios e criar alerta | K15: Verificação periódica | L15: SCR-INTERNO | M15: Médio | N15: Quando veículo compatível surgir | O15: Sim | P15: Defina critérios claros para não perder a oportunidade. | Q15: Veículo encontrado; Futuro
A16: INT-Q07 | B16: Internet | C16: Qualificação | D16: Interesse enfraquecido | E16: Cliente respondeu, mas não demonstra prioridade ou prazo | F16: Informado | G16: Vendedor | H16: Frio | I16: Definir continuidade | J16: Confirmar se ainda deseja acompanhamento | K16: CAD-03 | L16: SCR-REATIVACAO-CAD03-T1 | M16: Baixo | N16: Tentativa vence hoje | O16: Sim | P16: Descubra se há oportunidade real ou se deve programar futuro. | Q16: Retoma; Futuro; Encerrar
A17: INT-Q08 | B17: Internet | C17: Qualificação | D17: Cliente quente sem visita | E17: Existe intenção clara de compra e falta gerar compromisso presencial | F17: Sugerido | G17: Vendedor | H17: Quente | I17: Gerar visita | J17: Convidar para visita | K17: CAD-02 | L17: SCR-VISITA-CAD02-T1 | M17: Alto | N17: Tentativa vence hoje | O17: Sim | P17: Cliente tem intenção. O próximo avanço é presença na loja. | Q17: Visita em definição; Visita agendada; Objeção
A18: INT-V01 | B18: Internet | C18: Visita | D18: Data da visita em definição | E18: Cliente aceitou visitar, mas ainda não definiu dia e hora | F18: Informado | G18: Vendedor/Cliente | H18: Quente | I18: Definir compromisso | J18: Oferecer duas opções de horário | K18: CAD-05 | L18: SCR-VISITA-DATA-T1 | M18: Alto | N18: Tentativa vence hoje | O18: Sim | P18: Não deixe o aceite sem data; transforme intenção em agenda. | Q18: Agendou; Pediu para definir depois; Desistiu
A19: INT-V02 | B19: Internet | C19: Visita | D19: Visita agendada | E19: Existe data futura superior à janela de confirmação | F19: Automático | G19: Data | H19: Quente | I19: Preservar compromisso | J19: Aguardar janela de confirmação | K19: Derivada pela data | L19: SCR-CONFIRMAR-D2 | M19: Alto | N19: Somente quando entrar D-2/D-1/D0 | O19: Sim | P19: Visita futura cadastrada fortalece a carteira, mas só vira Central no dia/janela certa. | Q19: D-2; Reagendou; Cancelou
A20: INT-V03 | B20: Internet | C20: Visita | D20: Visita a confirmar | E20: Visita entrou na janela D-2 ou D-1 | F20: Derivado | G20: Vendedor | H20: Quente | I20: Confirmar visita | J20: Confirmar visita | K20: CAD-06 | L20: SCR-CONFIRMAR-D1 | M20: Alto | N20: Hoje | O20: Sim | P20: Proteja o comparecimento. Cliente marcado e não confirmado é risco. | Q20: Confirmou; Reagendou; Cancelou
A21: INT-V04 | B21: Internet | C21: Visita | D21: Visita confirmada | E21: Cliente confirmou presença | F21: Informado | G21: Cliente/Data | H21: Quente | I21: Preparar atendimento | J21: Aguardar data | K21: Derivada | L21: SCR-CONFIRMAR-D0 | M21: Alto | N21: Quando for hoje | O21: Sim | P21: Prepare o atendimento e mantenha o compromisso vivo. | Q21: Visita hoje; Cancelou; Reagendou
... A37: INT-N12 | B37: Internet | C37: Negociação | D37: Pronto para fechamento | E37: Barreiras resolvidas e falta formalizar a compra | F37: Informado/Derivado | G37: Vendedor | H37: Quente | I37: Formalizar venda | J37: Confirmar aceite e próximos dados | K37: Imediata | L37: SCR-FECHAMENTO-01 | M37: Muito alto | N37: Hoje | O37: Sim | P37: Não deixe fechamento esfriar; formalize o compromisso. | Q37: Venda acordada; Sinal; Perda
A38: POR-A01 | B38: Porta | C38: Visita | D38: Atendimento espontâneo em andamento | E38: Cliente entrou na loja espontaneamente e está sendo atendido | F38: Informado | G38: Vendedor | H38: Quente | I38: Realizar atendimento | J38: Diagnosticar e apresentar solução | K38: Sem cadência | L38: SCR-INTERNO | M38: Muito alto | N38: Não entra enquanto em atendimento | O38: Sim | P38: Atenda e registre apenas o que importa. | Q38: Venda; Proposta; Perda; Pós-visita | R38: Canal de entrada Porta.
A39: POR-A02 | B39: Porta | C39: Visita | D39: Atendimento concluído — desfecho pendente | E39: Atendimento encerrou, mas falta informar resultado | F39: Informado | G39: Vendedor | H39: Quente | I39: Registrar resultado | J39: Informar o que aconteceu | K39: Mesmo dia | L39: SCR-INTERNO | M39: Muito alto | N39: Hoje | O39: Sim | P39: Sem desfecho, a gestão perde a oportunidade. | Q39: Venda; Visitou e não comprou; Perda
A40: POR-A03 | B40: Porta | C40: Negociação | D40: Visitou e não comprou | E40: Cliente visitou espontaneamente e não finalizou a compra | F40: Informado | G40: Vendedor | H40: Quente | I40: Manter negociação viva | J40: Enviar resumo e retomar conversa | K40: CAD-03 | L40: SCR-POS-VISITA-01 | M40: Alto | N40: Hoje | O40: Sim | P40: A visita já aconteceu; agora o foco é recuperar decisão. | Q40: Proposta; Objeção; Venda; Perda; Futuro | R40: Se vender depois por follow-up, canalVenda pode ser Carteira.
A41: POR-A04 | B41: Porta | C41: Negociação | D41: Pós-visita sem resposta | E41: Vendedor fez follow-up após visita e cliente não respondeu | F41: Derivado | G41: Cliente | H41: Morno/Quente | I41: Recuperar oportunidade | J41: Executar tentativa de follow-up | K41: CAD-03 | L41: SCR-POS-VISITA-CAD03-T{n} | M41: Alto | N41: Tentativa vence hoje | O41: Sim | P41: Cliente que visitou tem valor maior que lead frio. | Q41: Respondeu; Proposta; Perda; Futuro
A42: CAR-C01 | B42: Carteira | C42: Contato | D42: Indicação recebida — contato pendente | E42: Vendedor recebeu indicação e ainda não iniciou conversa | F42: Informado | G42: Vendedor | H42: Morno | I42: Iniciar conversa | J42: Abordar mencionando a indicação | K42: CAD-01 | L42: SCR-CAR-INDICACAO-01 | M42: Médio | N42: Próxima ação hoje | O42: Sim | P42: Use a indicação como ponte de confiança. | Q42: Respondeu; Sem resposta; Inválido
A43: CAR-C02 | B43: Carteira | C43: Contato | D43: Prospecção própria — contato pendente | E43: Vendedor identificou oportunidade por iniciativa própria | F43: Informado | G43: Vendedor | H43: Morno | I43: Iniciar conversa | J43: Executar abordagem de prospecção | K43: CAD-01 | L43: SCR-CAR-PROSPECCAO-01 | M43: Médio | N43: Próxima ação hoje | O43: Sim | P43: O motivo real do contato deve estar claro. | Q43: Respondeu; Sem resposta; Sem interesse
A44: CAR-C03 | B44: Carteira | C44: Contato | D44: Cliente antigo — reativação pendente | E44: Cliente antigo ou parado deve ser reativado | F44: Sugerido | G44: Vendedor | H44: Frio/Morno | I44: Retomar relacionamento | J44: Fazer abordagem de reativação | K44: CAD-03 | L44: SCR-CAR-REATIVACAO-T1 | M44: Médio | N44: Tentativa vence hoje | O44: Sim | P44: Retomar histórico antes de tentar vender. | Q44: Respondeu; Sem resposta; Futuro
A45: CAR-C04 | B45: Carteira | C45: Contato | D45: Lead antigo acima de 90 dias | E45: Lead antigo será trabalhado como Carteira | F45: Derivado | G45: Vendedor | H45: Frio/Morno | I45: Reativar oportunidade | J45: Retomar com novo contexto | K45: CAD-03 | L45: SCR-CAR-REATIVACAO-T1 | M45: Médio | N45: Tentativa vence hoje | O45: Sim | P45: Preserve canalEntrada original e canalVenda Carteira se vender. | Q45: Respondeu; Sem resposta; Futuro
A46: CAR-C05 | B46: Carteira | C46: Contato | D46: Contato de anúncio próprio | E46: Cliente veio de anúncio próprio do vendedor | F46: Informado | G46: Vendedor | H46: Morno | I46: Iniciar conversa | J46: Responder e qualificar | K46: CAD-01 | L46: SCR-CAR-PROSPECCAO-01 | M46: Médio | N46: Próxima ação hoje | O46: Sim | P46: Origem detalhada: marketplace/OLX/tráfego próprio. | Q46: Respondeu; Sem resposta
A47: CAR-C06 | B47: Carteira | C47: Qualificação | D47: Cliente procurou diretamente o vendedor | E47: Cliente buscou o vendedor por relacionamento direto | F47: Informado | G47: Vendedor | H47: Morno/Quente | I47: Qualificar intenção | J47: Entender necessidade e prazo | K47: CAD-04 | L47: SCR-QUAL-01 | M47: Médio | N47: Hoje | O47: Sim | P47: Aproveite confiança existente para qualificar rápido. | Q47: Qualificado; Visita; Proposta
A48: CAR-C07 | B48: Carteira | C48: Relacionamento | D48: Oportunidade de troca ativada | E48: Cliente entrou em ciclo de troca/recompra | F48: Derivado/Informado | G48: Vendedor | H48: Morno/Quente | I48: Criar nova compra | J48: Entender intenção de troca | K48: CAD-04 | L48: SCR-TROCA-FUTURA-01 | M48: Médio | N48: Na data de ativação | O48: Sim | P48: Transforme relacionamento em nova oportunidade. | Q48: Qualificação; Visita; Futuro
A49: CAR-C08 | B49: Carteira | C49: Relacionamento | D49: Cliente de pós-venda com potencial | E49: Pós-venda indica oportunidade de indicação/troca | F49: Sugerido | G49: Vendedor | H49: Morno | I49: Gerar nova oportunidade | J49: Conversar sobre momento atual | K49: CAD-04 | L49: SCR-POSVENDA-01 | M49: Médio | N49: Quando marco vence | O49: Sim | P49: Pós-venda bem feito pode gerar indicação ou recompra. | Q49: Indicação; Troca; Sem oportunidade
A50: TR-01 | B50: Compartilhado | C50: Troca | D50: Aguardando dados do carro da troca | E50: Cliente informou troca, mas faltam dados básicos | F50: Informado/Derivado | G50: Cliente | H50: Quente | I50: Obter informações | J50: Solicitar placa, versão, ano, km e fotos | K50: CAD-08 | L50: SCR-TROCA-DADOS-T1 | M50: Alto | N50: Tentativa vence hoje | O50: Sim | P50: Solicite dados antes de estimar valor. | Q50: Dados recebidos; Avaliação presencial; Sem troca
A51: TR-02 | B51: Compartilhado | C51: Troca | D51: Dados recebidos — avaliação pendente | E51: Dados mínimos recebidos precisam ser analisados | F51: Informado/Derivado | G51: Loja | H51: Quente | I51: Conseguir avaliação | J51: Encaminhar para avaliação | K51: CAD-11 | L51: SCR-INTERNO | M51: Alto | N51: Verificação interna hoje | O51: Sim | P51: A pendência agora é interna, não do cliente. | Q51: Avaliação em andamento; Valor definido
A52: TR-03 | B52: Compartilhado | C52: Troca | D52: Avaliação presencial necessária | E52: Loja precisa ver o veículo fisicamente | F52: Informado/Derivado | G52: Vendedor/Cliente | H52: Quente | I52: Levar veículo à loja | J52: Agendar avaliação presencial | K52: CAD-02 | L52: SCR-VISITA-CAD02-T1 | M52: Alto | N52: Tentativa vence hoje | O52: Sim | P52: Agora sim o próximo passo é agendar visita/avaliação. | Q52: Agendou; Não quer levar; Futuro
... A89: REL-09 | B89: Compartilhado | C89: Relacionamento | D89: Garantia resolvida | E89: Problema solucionado | F89: Automático/Configurável | G89: Vendedor | H89: - | I89: Recuperar confiança | J89: Confirmar satisfação | K89: Hoje | L89: SCR-GARANTIA-RESOLVIDA | M89: Médio | N89: Hoje | O89: Sim | P89: Feche o ciclo de garantia com relacionamento. | Q89: Satisfeito; Nova ação

Sheet 03 Cadências
A1: Biblioteca de Cadências
A2: A cadência pertence ao objetivo comercial, não apenas ao canal.
A3: Cadência ID | B3: Nome | C3: Objetivo principal | D3: Tentativas | E3: Padrão de dias | F3: Aplicação | G3: Condição de interrupção | H3: Condição final
A4: CAD-01 | B4: Iniciar conversa em 14 dias | C4: Conseguir resposta inicial | D4: 6 | E4: D0, D+1, D+2, D+3, D+7, D+13 | F4: Lead sem resposta, indicação sem resposta, contato inicial, prospecção inicial | G4: Cliente respondeu | H4: Cadência concluída sem resposta
A5: CAD-02 | B5: Gerar visita em 21 dias | C5: Transformar interesse em compromisso presencial | D5: 6 | E5: D0, D+2, D+8, D+11, D+16, D+20 | F5: Cliente qualificado sem visita, cliente quente sem visita, avaliação presencial necessária | G5: Cliente agendou visita | H5: Elegível para Plano de Ataque ou futuro
A6: CAD-03 | B6: Recuperar negociação em 60 dias | C6: Retomar proposta, decisão ou negociação parada | D6: 6 | E6: D0, D+3, D+9, D+19, D+29, D+59 | F6: Proposta, pós-visita, decisão, objeções, negociação paralisada, reativação relevante | G6: Cliente respondeu ou decidiu | H6: Elegível para Plano de Ataque
A7: CAD-04 | B7: Completar qualificação em 7 dias | C7: Entender necessidade, veículo, prazo, troca e financiamento | D7: 4 | E7: D0, D+1, D+3, D+7 | F7: Qualificação inicial, definir veículo, entender viabilidade | G7: Cliente qualificado ou compra futura | H7: Retomar depois ou encerrar
A8: CAD-05 | B8: Definir data da visita em 7 dias | C8: Converter aceite de visita em data/hora | D8: 4 | E8: D0, D+1, D+3, D+7 | F8: Cliente aceitou visitar, mas ainda não definiu data e hora | G8: Data/hora definidas | H8: Reclassificar como cliente sem visita ou futuro
A9: CAD-06 | B9: Confirmar visita | C9: Proteger comparecimento à loja | D9: 3 | E9: D-2, D-1, D0 | F9: Visitas agendadas | G9: Cliente confirmou ou reagendou | H9: Se não compareceu, iniciar CAD-07
A10: CAD-07 | B10: Recuperar não comparecimento | C10: Reagendar visita perdida | D10: 5 | E10: D0, D+1, D+3, D+7, D+14 | F10: Cliente agendou e não compareceu | G10: Reagendou ou explicou motivo | H10: Contato futuro, perda ou Plano de Ataque
A11: CAD-08 | B11: Pendência comercial em 7 dias | C11: Coletar dados, documentos ou informação pendente | D11: 4 | E11: D0, D+1, D+3, D+7 | F11: Dados da troca, documentos, dados para simulação, pendências do cliente | G11: Pendência resolvida | H11: Status de bloqueio ou perda/futuro
A12: CAD-09 | B12: Converter financiamento aprovado | C12: Transformar aprovação em fechamento | D12: 4 | E12: D0, D+1, D+3, D+7 | F12: Financiamento aprovado sem compra | G12: Cliente aceita avançar ou objeção definida | H12: Retomar negociação ou perda
A13: CAD-10 | B13: Aguardar decisão de terceiro | C13: Envolver decisor ou trazer clareza | D13: 5 | E13: D0, D+2, D+5, D+10, D+14 | F13: Decisão depende de cônjuge, sócio ou familiar | G13: Decisor envolvido ou decisão tomada | H13: Follow-up de decisão ou futuro
A14: CAD-11 | B14: Verificação interna | C14: Cobrar retorno interno sem pressionar cliente | D14: Variável | E14: Todo dia útil ou a cada 2 dias úteis | F14: Aguardando loja, financeira ou garantia | G14: Pendência interna resolvida | H14: Escalar para gestor se atrasado
A15: CAD-12 | B15: Contato futuro | C15: Retomar na data correta | D15: 1 | E15: Data programada | F15: Compra futura, contato futuro, oportunidade futura | G15: Data chega e oportunidade reativa | H15: Retorna à Carteira Ativa
A16: CAD-13 | B16: Pós-venda | C16: Relacionamento e novas oportunidades | D16: Marcos | E16: D+7, D+30, D+180, 12m, 18m, 24m | F16: Pós-venda configurável por loja | G16: Cada marco executado | H16: Novo ciclo de troca/recompra ou encerramento

Sheet 04 Passos_Cadência
A1: Passos por Cadência
A2: Estratégia por tentativa/marco.
A3: Cadência ID | B3: Tentativa/Marco | C3: Offset | D3: Objetivo da tentativa | E3: Observação
A4: CAD-01 | B4: 1 | C4: D0 | D4: Primeira abordagem consultiva | E4: Iniciar conversa com contexto do veículo
A5: CAD-01 | B5: 2 | C5: D+1 | D5: Confirmação curta de interesse | E5: Facilitar resposta
A6: CAD-01 | B6: 3 | C6: D+2 | D6: Pergunta simples | E6: Reduzir atrito
A7: CAD-01 | B7: 4 | C7: D+3 | D7: Nova abordagem de valor | E7: Abrir alternativa de visita ou informação
A8: CAD-01 | B8: 5 | C8: D+7 | D8: Permissão para acompanhamento futuro | E8: Evitar insistência sem contexto
A9: CAD-01 | B9: 6 | C9: D+13 | D9: Encerramento respeitoso | E9: Preservar relacionamento
A10: CAD-02 | B10: 1 | C10: D0 | D10: Convite com duas opções | E10: Gerar compromisso
A11: CAD-02 | B11: 2 | C11: D+2 | D11: Reforçar benefício da visita | E11: Mostrar valor da presença
A12: CAD-02 | B12: 3 | C12: D+8 | D12: Perguntar melhor período | E12: Facilitar agenda
A13: CAD-02 | B13: 4 | C13: D+11 | D13: Nova disponibilidade | E13: Abrir alternativa
A14: CAD-02 | B14: 5 | C14: D+16 | D14: Entender barreira de visita | E14: Descobrir impedimento
... A60: CAD-13 | B60: 24 meses | C60: 24m | D60: Recompra ou troca | E60: Configurável

Sheet 05 Scripts
A1: Biblioteca Determinística de Scripts
A2: Scripts prontos por objetivo/tentativa. IA futura pode personalizar, mas não deve alterar a lógica.
A3: Script ID | B3: Área | C3: Tentativa/Marco | D3: Objetivo | E3: Texto padrão
A4: SCR-INT-CAD01-T1 | B4: Internet | C4: Tentativa 1 | D4: Iniciar conversa | E4: Oi, {nome}! Tudo bem? Aqui é {vendedor}, da {loja}. Vi seu interesse no {veiculo} e quero te ajudar com as informações certas. Você pensa em comprar agora ou ainda está pesquisando opções?
A5: SCR-INT-CAD01-T2 | B5: Internet | C5: Tentativa 2 | D5: Confirmar interesse | E5: Oi, {nome}! Só confirmando se recebeu minha mensagem sobre o {veiculo}. Qual informação te ajuda mais neste momento: valor, condições, troca ou financiamento?
A6: SCR-INT-CAD01-T3 | B6: Internet | C6: Tentativa 3 | D6: Facilitar resposta | E6: {nome}, para eu ser mais objetivo: você já definiu o veículo ou ainda está comparando algumas opções? Posso te ajudar a filtrar o que faz mais sentido.
A7: SCR-INT-CAD01-T4 | B7: Internet | C7: Tentativa 4 | D7: Abrir alternativa | E7: Posso te explicar tudo por aqui ou separar um horário para você conhecer melhor o {veiculo}. Qual formato fica mais fácil para você?
A8: SCR-INT-CAD01-T5 | B8: Internet | C8: Tentativa 5 | D8: Pedir permissão para seguir | E8: Oi, {nome}! Ainda faz sentido eu acompanhar sua busca pelo {veiculo}? Se o momento mudou, posso deixar registrado para falar com você mais adiante.
A9: SCR-INT-CAD01-T6 | B9: Internet | C9: Tentativa 6 | D9: Encerrar cadência respeitosamente | E9: Vou encerrar este acompanhamento por agora para não insistir. Quando quiser retomar a busca pelo {veiculo}, pode me chamar por aqui. Ficarei à disposição.
A10: SCR-CAR-INDICACAO-01 | B10: Carteira | C10: Inicial | D10: Iniciar conversa por indicação | E10: Oi, {nome}! Tudo bem? Sou {vendedor}, da {loja}. O {nomeIndicador} comentou que você está avaliando a compra ou troca de um veículo. Posso entender melhor o que você procura e te ajudar?
A11: SCR-CAR-PROSPECCAO-01 | B11: Carteira | C11: Inicial | D11: Prospecção direta | E11: Oi, {nome}! Tudo bem? Aqui é {vendedor}. Estou entrando em contato porque {motivoRealDoContato}. Você pensa em comprar ou trocar de veículo agora ou está se planejando para mais adiante?
A12: SCR-CAR-REATIVACAO-T1 | B12: Carteira | C12: Tentativa 1 | D12: Reativar relacionamento | E12: Oi, {nome}! Tudo bem? Estou atualizando meus acompanhamentos e queria saber se a ideia de comprar ou trocar de veículo ainda está nos seus planos. Se fizer sentido, posso retomar sua busca e te ajudar com as opções atuais.
A13: SCR-CAR-REATIVACAO-T2 | B13: Carteira | C13: Tentativa 2 | D13: Atualizar necessidade | E13: {nome}, seu interesse continua relacionado ao {veiculo} ou sua necessidade mudou? Com essa informação consigo te orientar melhor.
A14: SCR-CAR-REATIVACAO-T3 | B14: Carteira | C14: Tentativa 3 | D14: Descobrir barreira | E14: Hoje, o que seria mais importante para você retomar essa compra: veículo, valor, entrada, parcela ou troca?
... A80: SCR-INTERNO | B80: Interno | C80: Não enviar ao cliente | D80: Registro interno | E80: Ação interna. Não enviar mensagem ao cliente sem informação confirmada.

Sheet 06 Transições
A1: Resultados e Transições
A2: O vendedor informa o resultado; o Mentor calcula o novo status e decisão.
A3: Família | B3: Status/Contexto de origem | C3: Resultado informado | D3: Novo status sugerido | E3: Nova decisão / observação
A4: Contato | B4: Primeiro contato pendente | C4: Mensagem enviada | D4: Sem resposta — cadência ativa | E4: Avança para CAD-01 e agenda próxima tentativa
A5: Contato | B5: Sem resposta — cadência ativa | C5: Cliente respondeu | D5: Resposta recebida — atendimento pendente | E5: Interrompe cadência e coloca responsabilidade no vendedor
A6: Contato | B6: Sem resposta — cadência ativa | C6: Não respondeu à última tentativa | D6: Cadência concluída sem resposta | E6: Sai da Carteira Ativa e fica elegível para Plano de Ataque
A7: Contato | B7: Qualquer | C7: Número inválido | D7: Contato inválido | E7: Tentar corrigir contato antes de encerrar
A8: Contato | B8: Qualquer | C8: Não deseja contato | D8: Cliente não deseja contato | E8: Encerrar sem insistência
A9: Qualificação | B9: Qualificação inicial pendente | C9: Não definiu o carro | D9: Veículo ainda não definido | E9: Próximo passo: identificar modelo/categoria/faixa
A10: Qualificação | B10: Qualificação | C10: Definiu veículo | D10: Veículo definido — condição não qualificada | E10: Próximo passo: entender prazo, troca e financiamento
A11: Qualificação | B11: Veículo definido | C11: Compra agora e está qualificado | D11: Cliente qualificado sem visita | E11: Próximo passo: convidar para visita
A12: Qualificação | B12: Qualquer | C12: Compra futura | D12: Compra planejada para o futuro | E12: Programar data de retomada
A13: Qualificação | B13: Qualquer | C13: Não existe veículo adequado | D13: Aguardando veículo compatível | E13: Registrar critérios e criar alerta
A14: Visita | B14: Data da visita em definição | C14: Escolheu data e hora | D14: Visita agendada | E14: Aplicar regra de confirmação conforme data
... A55: Garantia | B55: Garantia resolvida | C55: Confirmou satisfação | D55: Garantia resolvida | E55: Encerrar ciclo ou gerar relacionamento

Sheet 07 Score_Prioridade
A1: Score, Qualidade da Carteira e Prioridade Comercial
A2: O score mede a qualidade da condução comercial da oportunidade. A prioridade combina urgência, potencial e risco de condução.
A4: Pilar | B4: Peso | C4: Regra para pontuação total | D4: Regra parcial | E4: Regra zero
A5: Status definido e coerente | B5: 15 | C5: Status válido e campos obrigatórios completos | D5: Status válido com informação pendente = 8 | E5: Status genérico, incoerente ou ausente = 0
A6: Próximo passo, responsável e data | B6: 20 | C6: Próximo passo, responsável e data definidos | D6: Próximo passo sem data/responsável = 10 | E6: Sem próximo passo = 0
A7: Execução dentro do prazo | B7: 30 | C7: Nada vencido | D7: Ação vence hoje = 25; atraso <24h = 10 | E7: Atraso >24h ou cliente respondeu sem retorno = 0
A8: Cadência respeitada | B8: 20 | C8: Tentativas devidas executadas | D8: Uma tentativa fora do prazo = 10 | E8: Tentativa ignorada/interrompida sem justificativa = 0
A9: Histórico atualizado | B9: 15 | C9: Último contato e resultado registrados | D9: Contato registrado sem resultado suficiente = 8 | E9: Histórico não representa atendimento atual = 0
A12: Tipo | B12: Evento | C12: Impacto sugerido | D12: Observação
A13: Perda de score | B13: Sem próxima ação definida | C13: -20 | D13: Usar como alerta além da fórmula dos pilares
A14: Perda de score | B14: Próxima ação vencida | C14: -25 | D14: Se ultrapassar prazo configurado
A15: Perda de score | B15: Cliente respondeu e vendedor não tratou | C15: -30 | D15: Principal risco operacional
A16: Perda de score | B16: Cliente quente parado há 5 dias | C16: -20 | D16: Cliente de alto potencial sem evolução
A17: Perda de score | B17: Proposta sem retorno e sem ação | C17: -20 | D17: Ação deveria estar programada
A18: Perda de score | B18: Histórico desatualizado | C18: -10 | D18: Não representa atendimento atual
A19: Perda de score | B19: Cadência interrompida sem justificativa | C19: -15 | D19: Não punir falta de resposta do cliente
A20: Recuperação | B20: Próxima ação criada | C20: +10 | D20: Até limite de 100
A21: Recuperação | B21: Próximo passo executado no prazo | C21: +10 | D21: Ação real do vendedor
A22: Recuperação | B22: Histórico atualizado | C22: +5 | D22: Evidência de condução
A23: Recuperação | B23: Cliente evoluiu de situação | C23: +10 | D23: Mudança positiva no acompanhamento
... A27: Recuperação | B27: Pós-venda realizado | C27: +10 | D27: Relacionamento continuado
A30: Potencial | B30: Pontuação usada no simulador | C30: Exemplos de status
A31: Muito alto | B31: 100 | C31: Visita hoje; Pronto para fechamento; Financiamento aprovado; Negociação ativa
A32: Alto | B32: 75 | C32: Proposta enviada; Visita confirmada; Objeção ativa; Cliente qualificado sem visita
A33: Médio | B33: 50 | C33: Cliente respondeu; Em qualificação; Pós-venda com potencial
A34: Baixo | B34: 25 | C34: Primeiro contato sem resposta; Compra futura; Cadência encerrada
A37: Índice calculado | B37: Prioridade
A38: 85 a 100 | B38: Máxima
A39: 70 a 84 | B39: Alta
A40: 50 a 69 | B40: Média
A41: 0 a 49 | B41: Baixa

Sheet 08 Plano_Ataque
A1: Plano de Ataque — Missões e Bloqueios
A2: O Plano de Ataque nasce das situações do Mentor Comercial. Ele não é campanha genérica.
A4: Condição encontrada no Mentor | B4: Missão sugerida | C4: Objetivo | D4: Quando aparece | E4: Observações
A5: Cadência encerrada sem resposta | B5: Retomar leads | C5: Tentar nova abordagem em grupo | D5: Após tentativas concluídas sem resposta | E5: Não é perda automática
A6: Visitou e não comprou | B6: Recuperar visitas | C6: Retomar clientes com alta intenção | D6: Status POR-A03/POR-A04 ou visita realizada sem venda | E6: Prioridade relevante para aumento de conversão
A7: Proposta sem retorno | B7: Recuperar propostas | C7: Recuperar decisão | D7: Status INT-N03 ou equivalente | E7: Pode gerar vendas rápidas
A8: Não compareceu | B8: Reagendar visitas | C8: Transformar ausência em nova agenda | D8: Status INT-V07 | E8: Usar mensagem sem julgamento
A9: Financiamento aprovado sem fechamento | B9: Converter aprovações | C9: Fechar clientes com barreira de crédito superada | D9: Status FIN-06 | E9: Alta prioridade
A10: Cliente qualificado sem visita | B10: Gerar visitas | C10: Criar compromisso presencial | D10: INT-Q04/INT-Q08 | E10: Principal rotina de aquecimento
A11: Cliente antigo | B11: Reativar carteira | C11: Retomar relacionamento | D11: CAR-C03/CAR-C04 | E11: Canal de venda Carteira
A12: Pós-venda positivo | B12: Pedir indicações | C12: Gerar novas oportunidades | D12: REL-01/REL-02 com satisfação | E12: Não automatizar sem cuidado
A13: Troca futura ativada | B13: Campanha de troca | C13: Criar nova compra | D13: REL-04/REL-05/REL-06 | E13: Canal Carteira
A14: Garantia ativa | B14: Acompanhar garantias | C14: Proteger relacionamento | D14: REL-07/REL-08 | E14: Não é campanha de venda; é retenção
A17: Status da missão anterior | B17: Pode iniciar nova missão? | C17: Mensagem ao vendedor
A18: Envio de mensagens incompleto | B18: Não | C18: Finalize o envio das mensagens da missão atual antes de iniciar uma nova.
A19: Aguardando resposta do cliente | B19: Sim | C19: Você já fez sua parte nesta missão. Pode iniciar outra.
A20: Clientes aguardando ação do vendedor | B20: Não | C20: Você possui clientes que responderam e aguardam sua ação. Resolva esses retornos antes de iniciar uma nova missão.
A21: Status pendente há mais de 24h | B21: Não | C21: Antes de iniciar uma nova missão, registre o resultado dos contatos pendentes.

Sheet Listas
A1: Status ID | B1: Canal | C1: Urgência | D1: Pontuação
A2: INT-C01 | B2: Porta | C2: Cliente respondeu e aguarda vendedor | D2: 15
A3: INT-C02 | B3: Internet | C3: Ação vencida | D3: 8
A4: INT-C03 | B4: Carteira | C4: Ação hoje | D4: 0
A5: INT-C04 | C5: Ação amanhã | D5: 20
A6: INT-C05 | C6: Até 3 dias | D6: 10
A7: INT-C06 | C7: Ação futura | D7: 30
A8: INT-Q01 | D8: 25
A9: INT-Q02
A10: INT-Q03
A11: INT-Q04
A12: INT-Q05
A13: INT-Q06
A14: INT-Q07
A15: INT-Q08
A16: INT-V01
A17: INT-V02
A18: INT-V03
A19: INT-V04
A20: INT-V05
... A87: REL-09

Sheet 09 Teste_Clientes
A1: Simulador de Clientes — Mentor Comercial
A2: Preencha Canal, Status ID, Próxima ação, Urgência e os pontos dos pilares de score. As demais colunas consultam o dicionário de regras.
A4: Cliente | B4: Canal Comercial | C4: Origem Detalhada | D4: Status ID | E4: Status atual | F4: Família | G4: Responsável | H4: Temperatura | I4: Objetivo | J4: Próximo passo | K4: Cadência | L4: Script base | M4: Potencial | N4: Regra Central | O4: Por que está aqui | P4: Próxima ação | Q4: Urgência | R4: Pontos urgência | S4: Status coerente (0/15) | T4: Próximo passo/data (0/20) | U4: Execução prazo (0/30) | V4: Cadência (0/20) | W4: Histórico (0/15) | X4: Score | Y4: Classificação | Z4: Pontos Potencial | AA4: Risco Condução | AB4: Índice Prioridade | AC4: Prioridade | AD4: Ação na Central? | AE4: Observação do teste
A5: Daniel Santos | B5: Internet | C5: Meta Ads | D5: INT-C01 | E5: =IFERROR(VLOOKUP($D5,'02 Status'!$A:$R,4,FALSE),"") -> Primeiro contato pendente | F5: =IFERROR(VLOOKUP($D5,'02 Status'!$A:$R,3,FALSE),"") -> Contato | G5: =IFERROR(VLOOKUP($D5,'02 Status'!$A:$R,7,FALSE),"") -> Vendedor | H5: =IFERROR(VLOOKUP($D5,'02 Status'!$A:$R,8,FALSE),"") -> Morno | I5: =IFERROR(VLOOKUP($D5,'02 Status'!$A:$R,9,FALSE),"") -> Iniciar conversa | J5: =IFERROR(VLOOKUP($D5,'02 Status'!$A:$R,10,FALSE),"") -> Enviar primeira abordagem | K5: =IFERROR(VLOOKUP($D5,'02 Status'!$A:$R,11,FALSE),"") -> CAD-01 | L5: =IFERROR(VLOOKUP($D5,'02 Status'!$A:$R,12,FALSE),"") -> SCR-INT-CAD01-T1 | M5: =IFERROR(VLOOKUP($D5,'02 Status'!$A:$R,13,FALSE),"") -> Baixo | N5: =IFERROR(VLOOKUP($D5,'02 Status'!$A:$R,14,FALSE),"") -> Próxima ação hoje | O5: =IFERROR(VLOOKUP($D5,'02 Status'!$A:$R,16,FALSE),"") -> O objetivo é iniciar conversa sem parecer cobrança. | P5: 46233.989 | Q5: Ação hoje | R5: =IF(Q5="Cliente respondeu e aguarda vendedor",100,IF(Q5="Ação vencida",95,IF(Q5="Ação hoje",90,IF(Q5="Ação amanhã",75,IF(Q5="Até 3 dias",55,25))))) -> 90 | S5: 15 | T5: 20 | U5: 25 | V5: 20 | W5: 15 | X5: =SUM(S5:W5) -> 95 | Y5: =IF(X5>=90,"Excelente",IF(X5>=75,"Boa",IF(X5>=50,"Atenção","Crítica"))) -> Excelente | Z5: =IF(M5="Muito alto",100,IF(M5="Alto",75,IF(M5="Médio",50,25))) -> 25 | AA5: =100-X5 -> 5 | AB5: =ROUND(0.45*R5+0.35*Z5+0.2*AA5,0) -> 50 | AC5: =IF(AB5>=85,"Máxima",IF(AB5>=70,"Alta",IF(AB5>=50,"Média","Baixa"))) -> Média | AD5: =IF(OR(Q5="Cliente respondeu e aguarda vendedor",Q5="Ação vencida",Q5="Ação hoje"),"Sim","Não") -> Sim | AE5: Lead novo sem resposta.
A6: Maria Santos | B6: Internet | C6: Instagram Loja | D6: INT-Q08 | E6: =IFERROR(VLOOKUP($D6,'02 Status'!$A:$R,4,FALSE),"") -> Cliente quente sem visita | F6: =IFERROR(VLOOKUP($D6,'02 Status'!$A:$R,3,FALSE),"") -> Qualificação | G6: =IFERROR(VLOOKUP($D6,'02 Status'!$A:$R,7,FALSE),"") -> Vendedor | H6: =IFERROR(VLOOKUP($D6,'02 Status'!$A:$R,8,FALSE),"") -> Quente | I6: =IFERROR(VLOOKUP($D6,'02 Status'!$A:$R,9,FALSE),"") -> Gerar visita | J6: =IFERROR(VLOOKUP($D6,'02 Status'!$A:$R,10,FALSE),"") -> Convidar para visita | K6: =IFERROR(VLOOKUP($D6,'02 Status'!$A:$R,11,FALSE),"") -> CAD-02 | L6: =IFERROR(VLOOKUP($D6,'02 Status'!$A:$R,12,FALSE),"") -> SCR-VISITA-CAD02-T1 | M6: =IFERROR(VLOOKUP($D6,'02 Status'!$A:$R,13,FALSE),"") -> Alto | N6: =IFERROR(VLOOKUP($D6,'02 Status'!$A:$R,14,FALSE),"") -> Tentativa vence hoje | O6: =IFERROR(VLOOKUP($D6,'02 Status'!$A:$R,16,FALSE),"") -> Cliente tem intenção. O próximo avanço é presença na loja. | P6: 46233.989 | Q6: Ação hoje | R6: =IF(Q6="Cliente respondeu e aguarda vendedor",100,IF(Q6="Ação vencida",95,IF(Q6="Ação hoje",90,IF(Q6="Ação amanhã",75,IF(Q6="Até 3 dias",55,25))))) -> 90 | S6: 15 | T6: 20 | U6: 30 | V6: 20 | W6: 15 | X6: =SUM(S6:W6) -> 100 | Y6: =IF(X6>=90,"Excelente",IF(X6>=75,"Boa",IF(X6>=50,"Atenção","Crítica"))) -> Excelente | Z6: =IF(M6="Muito alto",100,IF(M6="Alto",75,IF(M6="Médio",50,25))) -> 75 | AA6: =100-X6 -> 0 | AB6: =ROUND(0.45*R6+0.35*Z6+0.2*AA6,0) -> 67 | AC6: =IF(AB6>=85,"Máxima",IF(AB6>=70,"Alta",IF(AB6>=50,"Média","Baixa"))) -> Média | AD6: =IF(OR(Q6="Cliente respondeu e aguarda vendedor",Q6="Ação vencida",Q6="Ação hoje"),"Sim","Não") -> Sim | AE6: Cliente quente sem visita.
A7: Fernanda Costa | B7: Internet | C7: Google Ads | D7: INT-V02 | E7: =IFERROR(VLOOKUP($D7,'02 Status'!$A:$R,4,FALSE),"") -> Visita agendada | F7: =IFERROR(VLOOKUP($D7,'02 Status'!$A:$R,3,FALSE),"") -> Visita | G7: =IFERROR(VLOOKUP($D7,'02 Status'!$A:$R,7,FALSE),"") -> Data | H7: =IFERROR(VLOOKUP($D7,'02 Status'!$A:$R,8,FALSE),"") -> Quente | I7: =IFERROR(VLOOKUP($D7,'02 Status'!$A:$R,9,FALSE),"") -> Preservar compromisso | J7: =IFERROR(VLOOKUP($D7,'02 Status'!$A:$R,10,FALSE),"") -> Aguardar janela de confirmação | K7: =IFERROR(VLOOKUP($D7,'02 Status'!$A:$R,11,FALSE),"") -> Derivada pela data | L7: =IFERROR(VLOOKUP($D7,'02 Status'!$A:$R,12,FALSE),"") -> SCR-CONFIRMAR-D2 | M7: =IFERROR(VLOOKUP($D7,'02 Status'!$A:$R,13,FALSE),"") -> Alto | N7: =IFERROR(VLOOKUP($D7,'02 Status'!$A:$R,14,FALSE),"") -> Somente quando entrar D-2/D-1/D0 | O7: =IFERROR(VLOOKUP($D7,'02 Status'!$A:$R,16,FALSE),"") -> Visita futura cadastrada fortalece a carteira, mas só vira Central no dia/janela certa. | P7: 46238.989 | Q7: Ação futura | R7: =IF(Q7="Cliente respondeu e aguarda vendedor",100,IF(Q7="Ação vencida",95,IF(Q7="Ação hoje",90,IF(Q7="Ação amanhã",75,IF(Q7="Até 3 dias",55,25))))) -> 25 | S7: 15 | T7: 20 | U7: 30 | V7: 20 | W7: 15 | X7: =SUM(S7:W7) -> 100 | Y7: =IF(X7>=90,"Excelente",IF(X7>=75,"Boa",IF(X7>=50,"Atenção","Crítica"))) -> Excelente | Z7: =IF(M7="Muito alto",100,IF(M7="Alto",75,IF(M7="Médio",50,25))) -> 75 | AA7: =100-X7 -> 0 | AB7: =ROUND(0.45*R7+0.35*Z7+0.2*AA7,0) -> 38 | AC7: =IF(AB7>=85,"Máxima",IF(AB7>=70,"Alta",IF(AB7>=50,"Média","Baixa"))) -> Baixa | AD7: =IF(OR(Q7="Cliente respondeu e aguarda vendedor",Q7="Ação vencida",Q7="Ação hoje"),"Sim","Não") -> Não | AE7: Visita futura, não deve entrar na Central ainda.
A8: Carlos Oliveira | B8: Internet | C8: Site | D8: INT-N03 | E8: =IFERROR(VLOOKUP($D8,'02 Status'!$A:$R,4,FALSE),"") -> Proposta sem retorno | F8: =IFERROR(VLOOKUP($D8,'02 Status'!$A:$R,3,FALSE),"") -> Negociação | G8: =IFERROR(VLOOKUP($D8,'02 Status'!$A:$R,7,FALSE),"") -> Vendedor | H8: =IFERROR(VLOOKUP($D8,'02 Status'!$A:$R,8,FALSE),"") -> Quente | I8: =IFERROR(VLOOKUP($D8,'02 Status'!$A:$R,9,FALSE),"") -> Recuperar decisão | J8: =IFERROR(VLOOKUP($D8,'02 Status'!$A:$R,10,FALSE),"") -> Retomar proposta | K8: =IFERROR(VLOOKUP($D8,'02 Status'!$A:$R,11,FALSE),"") -> CAD-03 | L8: =IFERROR(VLOOKUP($D8,'02 Status'!$A:$R,12,FALSE),"") -> SCR-PROPOSTA-CAD03-T1 | M8: =IFERROR(VLOOKUP($D8,'02 Status'!$A:$R,13,FALSE),"") -> Alto | N8: =IFERROR(VLOOKUP($D8,'02 Status'!$A:$R,14,FALSE),"") -> Hoje | O8: =IFERROR(VLOOKUP($D8,'02 Status'!$A:$R,16,FALSE),"") -> Retome a proposta para descobrir o ponto de trava. | P8: 46233.989 | Q8: Ação vencida | R8: =IF(Q8="Cliente respondeu e aguarda vendedor",100,IF(Q8="Ação vencida",95,IF(Q8="Ação hoje",90,IF(Q8="Ação amanhã",75,IF(Q8="Até 3 dias",55,25))))) -> 95 | S8: 15 | T8: 20 | U8: 10 | V8: 10 | W8: 8 | X8: =SUM(S8:W8) -> 63 | Y8: =IF(X8>=90,"Excelente",IF(X8>=75,"Boa",IF(X8>=50,"Atenção","Crítica"))) -> Atenção | Z8: =IF(M8="Muito alto",100,IF(M8="Alto",75,IF(M8="Médio",50,25))) -> 75 | AA8: =100-X8 -> 37 | AB8: =ROUND(0.45*R8+0.35*Z8+0.2*AA8,0) -> 76 | AC8: =IF(AB8>=85,"Máxima",IF(AB8>=70,"Alta",IF(AB8>=50,"Média","Baixa"))) -> Alta | AD8: =IF(OR(Q8="Cliente respondeu e aguarda vendedor",Q8="Ação vencida",Q8="Ação hoje"),"Sim","Não") -> Sim | AE8: Proposta sem retorno.
A9: Roberto Marinho | B9: Internet | C9: Meta Ads | D9: FIN-06 | E9: =IFERROR(VLOOKUP($D9,'02 Status'!$A:$R,4,FALSE),"") -> Financiamento aprovado sem fechamento | F9: =IFERROR(VLOOKUP($D9,'02 Status'!$A:$R,3,FALSE),"") -> Financiamento | G9: =IFERROR(VLOOKUP($D9,'02 Status'!$A:$R,7,FALSE),"") -> Vendedor | H9: =IFERROR(VLOOKUP($D9,'02 Status'!$A:$R,8,FALSE),"") -> Quente | I9: =IFERROR(VLOOKUP($D9,'02 Status'!$A:$R,9,FALSE),"") -> Converter aprovação | J9: =IFERROR(VLOOKUP($D9,'02 Status'!$A:$R,10,FALSE),"") -> Conduzir para fechamento | K9: =IFERROR(VLOOKUP($D9,'02 Status'!$A:$R,11,FALSE),"") -> CAD-09 | L9: =IFERROR(VLOOKUP($D9,'02 Status'!$A:$R,12,FALSE),"") -> SCR-FIN-APROVADO-T1 | M9: =IFERROR(VLOOKUP($D9,'02 Status'!$A:$R,13,FALSE),"") -> Muito alto | N9: =IFERROR(VLOOKUP($D9,'02 Status'!$A:$R,14,FALSE),"") -> Hoje | O9: =IFERROR(VLOOKUP($D9,'02 Status'!$A:$R,16,FALSE),"") -> Aprovação reduz barreira. Prioridade alta de fechamento. | P9: 46233.989 | Q9: Ação hoje | R9: =IF(Q9="Cliente respondeu e aguarda vendedor",100,IF(Q9="Ação vencida",95,IF(Q9="Ação hoje",90,IF(Q9="Ação amanhã",75,IF(Q9="Até 3 dias",55,25))))) -> 90 | S9: 15 | T9: 20 | U9: 25 | V9: 20 | W9: 15 | X9: =SUM(S9:W9) -> 95 | Y9: =IF(X9>=90,"Excelente",IF(X9>=75,"Boa",IF(X9>=50,"Atenção","Crítica"))) -> Excelente | Z9: =IF(M9="Muito alto",100,IF(M9="Alto",75,IF(M9="Médio",50,25))) -> 100 | AA9: =100-X9 -> 5 | AB9: =ROUND(0.45*R9+0.35*Z9+0.2*AA9,0) -> 77 | AC9: =IF(AB9>=85,"Máxima",IF(AB9>=70,"Alta",IF(AB9>=50,"Média","Baixa"))) -> Alta | AD9: =IF(OR(Q9="Cliente respondeu e aguarda vendedor",Q9="Ação vencida",Q9="Ação hoje"),"Sim","Não") -> Sim | AE9: Financiamento aprovado sem fechamento.
A10: Ana Flávia | B10: Porta | C10: Entrada espontânea | D10: POR-A03 | E10: =IFERROR(VLOOKUP($D10,'02 Status'!$A:$R,4,FALSE),"") -> Visitou e não comprou | F10: =IFERROR(VLOOKUP($D10,'02 Status'!$A:$R,3,FALSE),"") -> Negociação | G10: =IFERROR(VLOOKUP($D10,'02 Status'!$A:$R,7,FALSE),"") -> Vendedor | H10: =IFERROR(VLOOKUP($D10,'02 Status'!$A:$R,8,FALSE),"") -> Quente | I10: =IFERROR(VLOOKUP($D10,'02 Status'!$A:$R,9,FALSE),"") -> Manter negociação viva | J10: =IFERROR(VLOOKUP($D10,'02 Status'!$A:$R,10,FALSE),"") -> Enviar resumo e retomar conversa | K10: =IFERROR(VLOOKUP($D10,'02 Status'!$A:$R,11,FALSE),"") -> CAD-03 | L10: =IFERROR(VLOOKUP($D10,'02 Status'!$A:$R,12,FALSE),"") -> SCR-POS-VISITA-01 | M10: =IFERROR(VLOOKUP($D10,'02 Status'!$A:$R,13,FALSE),"") -> Alto | N10: =IFERROR(VLOOKUP($D10,'02 Status'!$A:$R,14,FALSE),"") -> Hoje | O10: =IFERROR(VLOOKUP($D10,'02 Status'!$A:$R,16,FALSE),"") -> A visita já aconteceu; agora o foco é recuperar decisão. | P10: 46233.989 | Q10: Ação hoje | R10: =IF(Q10="Cliente respondeu e aguarda vendedor",100,IF(Q10="Ação vencida",95,IF(Q10="Ação hoje",90,IF(Q10="Ação amanhã",75,IF(Q10="Até 3 dias",55,25))))) -> 90 | S10: 15 | T10: 20 | U10: 30 | V10: 20 | W10: 15 | X10: =SUM(S10:W10) -> 100 | Y10: =IF(X10>=90,"Excelente",IF(X10>=75,"Boa",IF(X10>=50,"Atenção","Crítica"))) -> Excelente | Z10: =IF(M10="Muito alto",100,IF(M10="Alto",75,IF(M10="Médio",50,25))) -> 75 | AA10: =100-X10 -> 0 | AB10: =ROUND(0.45*R10+0.35*Z10+0.2*AA10,0) -> 67 | AC10: =IF(AB10>=85,"Máxima",IF(AB10>=70,"Alta",IF(AB10>=50,"Média","Baixa"))) -> Média | AD10: =IF(OR(Q10="Cliente respondeu e aguarda vendedor",Q10="Ação vencida",Q10="Ação hoje"),"Sim","Não") -> Sim | AE10: Visitou e não comprou.
A11: João Pereira | B11: Internet | C11: Lead Loja | D11: TR-01 | E11: =IFERROR(VLOOKUP($D11,'02 Status'!$A:$R,4,FALSE),"") -> Aguardando dados do carro da troca | F11: =IFERROR(VLOOKUP($D11,'02 Status'!$A:$R,3,FALSE),"") -> Troca | G11: =IFERROR(VLOOKUP($D11,'02 Status'!$A:$R,7,FALSE),"") -> Cliente | H11: =IFERROR(VLOOKUP($D11,'02 Status'!$A:$R,8,FALSE),"") -> Quente | I11: =IFERROR(VLOOKUP($D11,'02 Status'!$A:$R,9,FALSE),"") -> Obter informações | J11: =IFERROR(VLOOKUP($D11,'02 Status'!$A:$R,10,FALSE),"") -> Solicitar placa, versão, ano, km e fotos | K11: =IFERROR(VLOOKUP($D11,'02 Status'!$A:$R,11,FALSE),"") -> CAD-08 | L11: =IFERROR(VLOOKUP($D11,'02 Status'!$A:$R,12,FALSE),"") -> SCR-TROCA-DADOS-T1 | M11: =IFERROR(VLOOKUP($D11,'02 Status'!$A:$R,13,FALSE),"") -> Alto | N11: =IFERROR(VLOOKUP($D11,'02 Status'!$A:$R,14,FALSE),"") -> Tentativa vence hoje | O11: =IFERROR(VLOOKUP($D11,'02 Status'!$A:$R,16,FALSE),"") -> Solicite dados antes de estimar valor. | P11: 46233.989 | Q11: Ação hoje | R11: =IF(Q11="Cliente respondeu e aguarda vendedor",100,IF(Q11="Ação vencida",95,IF(Q11="Ação hoje",90,IF(Q11="Ação amanhã",75,IF(Q11="Até 3 dias",55,25))))) -> 90 | S11: 15 | T11: 20 | U11: 30 | V11: 20 | W11: 8 | X11: =SUM(S11:W11) -> 93 | Y11: =IF(X11>=90,"Excelente",IF(X11>=75,"Boa",IF(X11>=50,"Atenção","Crítica"))) -> Excelente | Z11: =IF(M11="Muito alto",100,IF(M11="Alto",75,IF(M11="Médio",50,25))) -> 75 | AA11: =100-X11 -> 7 | AB11: =ROUND(0.45*R11+0.35*Z11+0.2*AA11,0) -> 68 | AC11: =IF(AB11>=85,"Máxima",IF(AB11>=70,"Alta",IF(AB11>=50,"Média","Baixa"))) -> Média | AD11: =IF(OR(Q11="Cliente respondeu e aguarda vendedor",Q11="Ação vencida",Q11="Ação hoje"),"Sim","Não") -> Sim | AE11: Aguardando dados da troca.
A12: Ricardo Santos | B12: Carteira | C12: Cliente antigo | D12: CAR-C03 | E12: =IFERROR(VLOOKUP($D12,'02 Status'!$A:$R,4,FALSE),"") -> Cliente antigo — reativação pendente | F12: =IFERROR(VLOOKUP($D12,'02 Status'!$A:$R,3,FALSE),"") -> Contato | G12: =IFERROR(VLOOKUP($D12,'02 Status'!$A:$R,7,FALSE),"") -> Vendedor | H12: =IFERROR(VLOOKUP($D12,'02 Status'!$A:$R,8,FALSE),"") -> Frio/Morno | I12: =IFERROR(VLOOKUP($D12,'02 Status'!$A:$R,9,FALSE),"") -> Retomar relacionamento | J12: =IFERROR(VLOOKUP($D12,'02 Status'!$A:$R,10,FALSE),"") -> Fazer abordagem de reativação | K12: =IFERROR(VLOOKUP($D12,'02 Status'!$A:$R,11,FALSE),"") -> CAD-03 | L12: =IFERROR(VLOOKUP($D12,'02 Status'!$A:$R,12,FALSE),"") -> SCR-CAR-REATIVACAO-T1 | M12: =IFERROR(VLOOKUP($D12,'02 Status'!$A:$R,13,FALSE),"") -> Médio | N12: =IFERROR(VLOOKUP($D12,'02 Status'!$A:$R,14,FALSE),"") -> Tentativa vence hoje | O12: =IFERROR(VLOOKUP($D12,'02 Status'!$A:$R,16,FALSE),"") -> Retomar histórico antes de tentar vender. | P12: 46236.989 | Q12: Até 3 dias | R12: =IF(Q12="Cliente respondeu e aguarda vendedor",100,IF(Q12="Ação vencida",95,IF(Q12="Ação hoje",90,IF(Q12="Ação amanhã",75,IF(Q12="Até 3 dias",55,25))))) -> 55 | S12: 15 | T12: 20 | U12: 30 | V12: 20 | W12: 15 | X12: =SUM(S12:W12) -> 100 | Y12: =IF(X12>=90,"Excelente",IF(X12>=75,"Boa",IF(X12>=50,"Atenção","Crítica"))) -> Excelente | Z12: =IF(M12="Muito alto",100,IF(M12="Alto",75,IF(M12="Médio",50,25))) -> 50 | AA12: =100-X12 -> 0 | AB12: =ROUND(0.45*R12+0.35*Z12+0.2*AA12,0) -> 42 | AC12: =IF(AB12>=85,"Máxima",IF(AB12>=70,"Alta",IF(AB12>=50,"Média","Baixa"))) -> Baixa | AD12: =IF(OR(Q12="Cliente respondeu e aguarda vendedor",Q12="Ação vencida",Q12="Ação hoje"),"Sim","Não") -> Não | AE12: Reativação de cliente antigo.
A13: Tatiane Souza | B13: Carteira | C13: Pós-venda | D13: REL-01 | E13: =IFERROR(VLOOKUP($D13,'02 Status'!$A:$R,4,FALSE),"") -> Pós-venda D+7 | F13: =IFERROR(VLOOKUP($D13,'02 Status'!$A:$R,3,FALSE),"") -> Relacionamento | G13: =IFERROR(VLOOKUP($D13,'02 Status'!$A:$R,7,FALSE),"") -> Vendedor | H13: =IFERROR(VLOOKUP($D13,'02 Status'!$A:$R,8,FALSE),"") -> - | I13: =IFERROR(VLOOKUP($D13,'02 Status'!$A:$R,9,FALSE),"") -> Verificar satisfação | J13: =IFERROR(VLOOKUP($D13,'02 Status'!$A:$R,10,FALSE),"") -> Fazer contato e pedir indicação | K13: =IFERROR(VLOOKUP($D13,'02 Status'!$A:$R,11,FALSE),"") -> CAD-13 | L13: =IFERROR(VLOOKUP($D13,'02 Status'!$A:$R,12,FALSE),"") -> SCR-POSVENDA-D7 | M13: =IFERROR(VLOOKUP($D13,'02 Status'!$A:$R,13,FALSE),"") -> Médio | N13: =IFERROR(VLOOKUP($D13,'02 Status'!$A:$R,14,FALSE),"") -> Quando marco vence | O13: =IFERROR(VLOOKUP($D13,'02 Status'!$A:$R,16,FALSE),"") -> Relacionamento bem feito gera indicação. | P13: 46233.989 | Q13: Ação hoje | R13: =IF(Q13="Cliente respondeu e aguarda vendedor",100,IF(Q13="Ação vencida",95,IF(Q13="Ação hoje",90,IF(Q13="Ação amanhã",75,IF(Q13="Até 3 dias",55,25))))) -> 90 | S13: 15 | T13: 20 | U13: 30 | V13: 20 | W13: 15 | X13: =SUM(S13:W13) -> 100 | Y13: =IF(X13>=90,"Excelente",IF(X13>=75,"Boa",IF(X13>=50,"Atenção","Crítica"))) -> Excelente | Z13: =IF(M13="Muito alto",100,IF(M13="Alto",75,IF(M13="Médio",50,25))) -> 50 | AA13: =100-X13 -> 0 | AB13: =ROUND(0.45*R13+0.35*Z13+0.2*AA13,0) -> 58 | AC13: =IF(AB13>=85,"Máxima",IF(AB13>=70,"Alta",IF(AB13>=50,"Média","Baixa"))) -> Média | AD13: =IF(OR(Q13="Cliente respondeu e aguarda vendedor",Q13="Ação vencida",Q13="Ação hoje"),"Sim","Não") -> Sim | AE13: Pós-venda D+7.
A14: Luiz Silva | B14: Carteira | C14: Garantia | D14: REL-07 | E14: =IFERROR(VLOOKUP($D14,'02 Status'!$A:$R,4,FALSE),"") -> Garantia aberta | F14: =IFERROR(VLOOKUP($D14,'02 Status'!$A:$R,3,FALSE),"") -> Relacionamento | G14: =IFERROR(VLOOKUP($D14,'02 Status'!$A:$R,7,FALSE),"") -> Vendedor/Loja | H14: =IFERROR(VLOOKUP($D14,'02 Status'!$A:$R,8,FALSE),"") -> - | I14: =IFERROR(VLOOKUP($D14,'02 Status'!$A:$R,9,FALSE),"") -> Proteger relacionamento | J14: =IFERROR(VLOOKUP($D14,'02 Status'!$A:$R,10,FALSE),"") -> Confirmar recebimento e orientar | K14: =IFERROR(VLOOKUP($D14,'02 Status'!$A:$R,11,FALSE),"") -> CAD-11 | L14: =IFERROR(VLOOKUP($D14,'02 Status'!$A:$R,12,FALSE),"") -> SCR-GARANTIA-01 | M14: =IFERROR(VLOOKUP($D14,'02 Status'!$A:$R,13,FALSE),"") -> Médio | N14: =IFERROR(VLOOKUP($D14,'02 Status'!$A:$R,14,FALSE),"") -> Quando acompanhamento vence | O14: =IFERROR(VLOOKUP($D14,'02 Status'!$A:$R,16,FALSE),"") -> Garantia é relação sensível, não apenas operação. | P14: 46233.989 | Q14: Ação hoje | R14: =IF(Q14="Cliente respondeu e aguarda vendedor",100,IF(Q14="Ação vencida",95,IF(Q14="Ação hoje",90,IF(Q14="Ação amanhã",75,IF(Q14="Até 3 dias",55,25))))) -> 90 | S14: 15 | T14: 20 | U14: 25 | V14: 20 | W14: 15 | X14: =SUM(S14:W14) -> 95 | Y14: =IF(X14>=90,"Excelente",IF(X14>=75,"Boa",IF(X14>=50,"Atenção","Crítica"))) -> Excelente | Z14: =IF(M14="Muito alto",100,IF(M14="Alto",75,IF(M14="Médio",50,25))) -> 50 | AA14: =100-X14 -> 5 | AB14: =ROUND(0.45*R14+0.35*Z14+0.2*AA14,0) -> 59 | AC14: =IF(AB14>=85,"Máxima",IF(AB14>=70,"Alta",IF(AB14>=50,"Média","Baixa"))) -> Média | AD14: =IF(OR(Q14="Cliente respondeu e aguarda vendedor",Q14="Ação vencida",Q14="Ação hoje"),"Sim","Não") -> Sim | AE14: Garantia aberta.
E15: =IFERROR(VLOOKUP($D15,'02 Status'!$A:$R,4,FALSE),"") | F15: =IFERROR(VLOOKUP($D15,'02 Status'!$A:$R,3,FALSE),"") | G15: =IFERROR(VLOOKUP($D15,'02 Status'!$A:$R,7,FALSE),"") | H15: =IFERROR(VLOOKUP($D15,'02 Status'!$A:$R,8,FALSE),"") | I15: =IFERROR(VLOOKUP($D15,'02 Status'!$A:$R,9,FALSE),"") | J15: =IFERROR(VLOOKUP($D15,'02 Status'!$A:$R,10,FALSE),"") | K15: =IFERROR(VLOOKUP($D15,'02 Status'!$A:$R,11,FALSE),"") | L15: =IFERROR(VLOOKUP($D15,'02 Status'!$A:$R,12,FALSE),"") | M15: =IFERROR(VLOOKUP($D15,'02 Status'!$A:$R,13,FALSE),"") | N15: =IFERROR(VLOOKUP($D15,'02 Status'!$A:$R,14,FALSE),"") | O15: =IFERROR(VLOOKUP($D15,'02 Status'!$A:$R,16,FALSE),"") | R15: =IF(Q15="Cliente respondeu e aguarda vendedor",100,IF(Q15="Ação vencida",95,IF(Q15="Ação hoje",90,IF(Q15="Ação amanhã",75,IF(Q15="Até 3 dias",55,25))))) -> 25 | X15: =SUM(S15:W15) -> 0 | Y15: =IF(X15>=90,"Excelente",IF(X15>=75,"Boa",IF(X15>=50,"Atenção","Crítica"))) -> Crítica | Z15: =IF(M15="Muito alto",100,IF(M15="Alto",75,IF(M15="Médio",50,25))) -> 25 | AA15: =100-X15 -> 100 | AB15: =ROUND(0.45*R15+0.35*Z15+0.2*AA15,0) -> 40 | AC15: =IF(AB15>=85,"Máxima",IF(AB15>=70,"Alta",IF(AB15>=50,"Média","Baixa"))) -> Baixa | AD15: =IF(OR(Q15="Cliente respondeu e aguarda vendedor",Q15="Ação vencida",Q15="Ação hoje"),"Sim","Não") -> Não
E16: =IFERROR(VLOOKUP($D16,'02 Status'!$A:$R,4,FALSE),"") | F16: =IFERROR(VLOOKUP($D16,'02 Status'!$A:$R,3,FALSE),"") | G16: =IFERROR(VLOOKUP($D16,'02 Status'!$A:$R,7,FALSE),"") | H16: =IFERROR(VLOOKUP($D16,'02 Status'!$A:$R,8,FALSE),"") | I16: =IFERROR(VLOOKUP($D16,'02 Status'!$A:$R,9,FALSE),"") | J16: =IFERROR(VLOOKUP($D16,'02 Status'!$A:$R,10,FALSE),"") | K16: =IFERROR(VLOOKUP($D16,'02 Status'!$A:$R,11,FALSE),"") | L16: =IFERROR(VLOOKUP($D16,'02 Status'!$A:$R,12,FALSE),"") | M16: =IFERROR(VLOOKUP($D16,'02 Status'!$A:$R,13,FALSE),"") | N16: =IFERROR(VLOOKUP($D16,'02 Status'!$A:$R,14,FALSE),"") | O16: =IFERROR(VLOOKUP($D16,'02 Status'!$A:$R,16,FALSE),"") | R16: =IF(Q16="Cliente respondeu e aguarda vendedor",100,IF(Q16="Ação vencida",95,IF(Q16="Ação hoje",90,IF(Q16="Ação amanhã",75,IF(Q16="Até 3 dias",55,25))))) -> 25 | X16: =SUM(S16:W16) -> 0 | Y16: =IF(X16>=90,"Excelente",IF(X16>=75,"Boa",IF(X16>=50,"Atenção","Crítica"))) -> Crítica | Z16: =IF(M16="Muito alto",100,IF(M16="Alto",75,IF(M16="Médio",50,25))) -> 25 | AA16: =100-X16 -> 100 | AB16: =ROUND(0.45*R16+0.35*Z16+0.2*AA16,0) -> 40 | AC16: =IF(AB16>=85,"Máxima",IF(AB16>=70,"Alta",IF(AB16>=50,"Média","Baixa"))) -> Baixa | AD16: =IF(OR(Q16="Cliente respondeu e aguarda vendedor",Q16="Ação vencida",Q16="Ação hoje"),"Sim","Não") -> Não
E17: =IFERROR(VLOOKUP($D17,'02 Status'!$A:$R,4,FALSE),"") | F17: =IFERROR(VLOOKUP($D17,'02 Status'!$A:$R,3,FALSE),"") | G17: =IFERROR(VLOOKUP($D17,'02 Status'!$A:$R,7,FALSE),"") | H17: =IFERROR(VLOOKUP($D17,'02 Status'!$A:$R,8,FALSE),"") | I17: =IFERROR(VLOOKUP($D17,'02 Status'!$A:$R,9,FALSE),"") | J17: =IFERROR(VLOOKUP($D17,'02 Status'!$A:$R,10,FALSE),"") | K17: =IFERROR(VLOOKUP($D17,'02 Status'!$A:$R,11,FALSE),"") | L17: =IFERROR(VLOOKUP($D17,'02 Status'!$A:$R,12,FALSE),"") | M17: =IFERROR(VLOOKUP($D17,'02 Status'!$A:$R,13,FALSE),"") | N17: =IFERROR(VLOOKUP($D17,'02 Status'!$A:$R,14,FALSE),"") | O17: =IFERROR(VLOOKUP($D17,'02 Status'!$A:$R,16,FALSE),"") | R17: =IF(Q17="Cliente respondeu e aguarda vendedor",100,IF(Q17="Ação vencida",95,IF(Q17="Ação hoje",90,IF(Q17="Ação amanhã",75,IF(Q17="Até 3 dias",55,25))))) -> 25 | X17: =SUM(S17:W17) -> 0 | Y17: =IF(X17>=90,"Excelente",IF(X17>=75,"Boa",IF(X17>=50,"Atenção","Crítica"))) -> Crítica | Z17: =IF(M17="Muito alto",100,IF(M17="Alto",75,IF(M17="Médio",50,25))) -> 25 | AA17: =100-X17 -> 100 | AB17: =ROUND(0.45*R17+0.35*Z17+0.2*AA17,0) -> 40 | AC17: =IF(AB17>=85,"Máxima",IF(AB17>=70,"Alta",IF(AB17>=50,"Média","Baixa"))) -> Baixa | AD17: =IF(OR(Q17="Cliente respondeu e aguarda vendedor",Q17="Ação vencida",Q17="Ação hoje"),"Sim","Não") -> Não
E18: =IFERROR(VLOOKUP($D18,'02 Status'!$A:$R,4,FALSE),"") | F18: =IFERROR(VLOOKUP($D18,'02 Status'!$A:$R,3,FALSE),"") | G18: =IFERROR(VLOOKUP($D18,'02 Status'!$A:$R,7,FALSE),"") | H18: =IFERROR(VLOOKUP($D18,'02 Status'!$A:$R,8,FALSE),"") | I18: =IFERROR(VLOOKUP($D18,'02 Status'!$A:$R,9,FALSE),"") | J18: =IFERROR(VLOOKUP($D18,'02 Status'!$A:$R,10,FALSE),"") | K18: =IFERROR(VLOOKUP($D18,'02 Status'!$A:$R,11,FALSE),"") | L18: =IFERROR(VLOOKUP($D18,'02 Status'!$A:$R,12,FALSE),"") | M18: =IFERROR(VLOOKUP($D18,'02 Status'!$A:$R,13,FALSE),"") | N18: =IFERROR(VLOOKUP($D18,'02 Status'!$A:$R,14,FALSE),"") | O18: =IFERROR(VLOOKUP($D18,'02 Status'!$A:$R,16,FALSE),"") | R18: =IF(Q18="Cliente respondeu e aguarda vendedor",100,IF(Q18="Ação vencida",95,IF(Q18="Ação hoje",90,IF(Q18="Ação amanhã",75,IF(Q18="Até 3 dias",55,25))))) -> 25 | X18: =SUM(S18:W18) -> 0 | Y18: =IF(X18>=90,"Excelente",IF(X18>=75,"Boa",IF(X18>=50,"Atenção","Crítica"))) -> Crítica | Z18: =IF(M18="Muito alto",100,IF(M18="Alto",75,IF(M18="Médio",50,25))) -> 25 | AA18: =100-X18 -> 100 | AB18: =ROUND(0.45*R18+0.35*Z18+0.2*AA18,0) -> 40 | AC18: =IF(AB18>=85,"Máxima",IF(AB18>=70,"Alta",IF(AB18>=50,"Média","Baixa"))) -> Baixa | AD18: =IF(OR(Q18="Cliente respondeu e aguarda vendedor",Q18="Ação vencida",Q18="Ação hoje"),"Sim","Não") -> Não
